export const CatchAsyncErrors = (theFunc) => (req,res,next) => {
    Promise.resolve(theFunc(req,res,next)).catch(next)
} 